<mujoco model="apartment">
    <option timestep="0.005" integrator="RK4" gravity="0 0 -9.81">
        <flag sensornoise="disable" energy="disable" contact="enable" />
    </option>
    <compiler angle="radian"
        meshdir="iai_apartment_with_window4/meshes/"
        autolimits="true">
    </compiler>
    <default />
    <asset>
        <mesh name="armchair" file="armchair.stl" />
        <mesh name="sofa" file="sofa.stl" />
        <mesh name="SM_Fridge_Egg_Tray" file="SM_Fridge_Egg_Tray.stl" />
        <mesh name="SM_Dishwasher_Tray_01" file="SM_Dishwasher_Tray_01.stl" />
        <mesh name="SM_Dishwasher_Tray_02" file="SM_Dishwasher_Tray_02.stl" />
        <mesh name="SM_Dishwasher_Tray_03" file="SM_Dishwasher_Tray_03.stl" />
    </asset>

    <asset>
        <texture name="grid" type="2d" builtin="checker" width="512" height="512" rgb1=".1 .2 .3"
            rgb2=".2 .3 .4" />
        <material name="grid" texture="grid" texrepeat="1 1" texuniform="true" reflectance=".2" />
    </asset>
    <worldbody>
        <geom name="floor" size="0 0 .05" type="plane" material="grid" condim="3" />
        <light diffuse=".5 .5 .5" pos="0 0 5" dir="0 0 -1" />
    </worldbody>

    <worldbody>
        <body name="iai_apartment_with_window4" gravcomp="1">
            <geom size="1.0677 0.01 0.092776" pos="9.5211 5.12273 2.95028" type="box"/>
            <geom size="1.0677 0.01 0.18914" pos="9.5211 5.12273 2.31667" type="box"/>
            <geom size="1.0677 0.01 0.026796" pos="9.5211 5.12273 0.02664" type="box"/>
            <geom size="0.075574 0.01 1.52161" pos="8.52897 5.12273 1.52145" type="box"/>
            <geom size="0.075574 0.01 1.52161" pos="10.5132 5.12273 1.52145" type="box"/>
            <geom size="0.073126 0.01 1.52161" pos="9.5211 5.12273 1.52145" type="box"/>
            <geom size="1.525 9.475 0.0015" pos="9.45 0.135 1.53" quat="0.500398 0.499602 0.5 -0.5" type="box"/>
            <geom size="1.525 2.404 0.0015" pos="-0.005 2.532 1.53" quat="0.000563312 -0.706825 0.000562864 0.707388" type="box"/>
            <geom size="1.525 4.175 0.0015" pos="14.75 4.92578 1.53" quat="0.500398 -0.499602 0.5 0.5" type="box"/>
            <geom size="1.525 4.275 0.0015" pos="4.25 4.93414 1.53" quat="0.500398 -0.499602 0.5 0.5" type="box"/>
            <geom size="1.525 2.404 0.0015" pos="18.919 2.532 1.53" quat="0.707388 0 0.706825 0" type="box"/>
            <geom size="0.04 0.04 0.075" pos="18.2889 0.6687 0.075" type="box"/>
            <geom size="0.04 0.04 0.075" pos="18.6642 0.6687 0.075" type="box"/>
            <geom size="0.04 0.04 0.075" pos="18.2889 1.5651 0.075" type="box"/>
            <geom size="0.04 0.04 0.075" pos="18.6642 1.5651 0.075" type="box"/>
            <geom size="0.2435 0.5 0.01345" pos="18.4777 1.1169 0.16345" type="box"/>
            <geom size="0.2435 0.01035 0.825" pos="18.4777 1.60655 0.975" type="box"/>
            <geom size="0.2159 0.009284 0.825" pos="18.4686 1.1169 0.975" type="box"/>
            <geom size="0.2435 0.01035 0.825" pos="18.4777 0.62725 0.975" type="box"/>
            <geom size="0.01835 0.5 0.825" pos="18.7028 1.1169 0.975" type="box"/>
            <geom size="0.01835 0.5 0.825" pos="18.7028 1.1169 0.975" type="box"/>
            <geom size="0.2435 0.5 0.0135" pos="18.4777 1.1169 1.7865" type="box"/>
            <geom size="0.21495 0.234979 0.0059" pos="18.4696 0.872557 0.5727" type="box"/>
            <geom size="0.21495 0.234979 0.0059" pos="18.4696 0.872557 0.974836" type="box"/>
            <geom size="0.21495 0.234979 0.0059" pos="18.4696 0.872557 1.37686" type="box"/>
            <geom size="0.0075 0.234949" pos="18.4713 1.36127 1.66898" quat="0.707105 0.707108 0 0" type="cylinder"/>
            <geom pos="16.8188 1.3709 0.355943" quat="0.573561 0 0 0.819163" type="mesh" mesh="armchair"/>
            <geom pos="17.0486 4.1596 0.35733" type="mesh" mesh="sofa"/>
            <geom size="0.29 0.54 0.02977" pos="16.6534 2.77957 0.02977" quat="0.707105 0 0 0.707108" type="box"/>
            <geom size="0.3053 0.2 0.00598" pos="16.6534 2.75747 0.06552" quat="0.707105 0 0 0.707108" type="box"/>
            <geom size="0.35 0.2 0.16" pos="16.2537 2.77957 0.220625" quat="0.707105 0 0 0.707108" type="box"/>
            <geom size="0.35 0.2 0.16" pos="17.0531 2.77957 0.220625" quat="0.707105 0 0 0.707108" type="box"/>
            <geom size="0.03365 0.2 0.16" pos="16.6534 3.09591 0.22" quat="0.707105 0 0 0.707108" type="box"/>
            <geom size="0.35 0.6 0.01" pos="16.6534 2.77957 0.39" quat="0.707105 0 0 0.707108" type="box"/>
            <geom size="0.156 0.156 0.23" pos="16.061 1.8796 0.229905" type="box"/>
            <geom size="0.0095 0.27747 1.06389" pos="0.274133 1.76676 1.16441" quat="0.707107 0 0 0.707107" type="box"/>
            <geom size="0.0095 0.27747 1.06389" pos="0.274133 1.18629 1.16441" quat="0.707107 0 0 0.707107" type="box"/>
            <geom size="0.280969 0.004 1.05589" pos="0.0126592 1.47666 1.1564" quat="0.707107 0 0 0.707107" type="box"/>
            <geom size="0.01046 0.287969 1.11388" pos="0.284632 1.16679 1.11441" quat="0.707107 0 0 0.707107" type="box"/>
            <geom size="0.280969 0.008 0.032" pos="0.539608 1.47666 2.18019" quat="0.707107 0 0 0.707107" type="box"/>
            <geom size="0.280969 0.270471 0.008" pos="0.279132 1.47666 2.22019" quat="0.707107 0 0 0.707107" type="box"/>
            <geom size="0.280969 0.270471 0.0075" pos="0.284132 1.47666 1.36391" quat="0.707107 0 0 0.707107" type="box"/>
            <geom size="0.280969 0.267471 0.0075" pos="0.284132 1.47666 0.753245" quat="0.707107 0 0 0.707107" type="box"/>
            <geom size="0.294945 0.272833 0.075421" pos="0.293813 1.47606 1.27827" quat="0.707107 0 0 0.707107" type="box"/>
            <geom size="0.294945 0.272833 0.022799" pos="0.293813 1.47606 0.789773" quat="0.707107 0 0 0.707107" type="box"/>
            <geom size="0.0295 0.272833 0.293011" pos="0.293813 1.21162 1.06068" quat="0.707107 0 0 0.707107" type="box"/>
            <geom size="0.027451 0.272833 0.293011" pos="0.293813 1.74322 1.06068" quat="0.707107 0 0 0.707107" type="box"/>
            <geom size="0.294945 0.037392 0.293011" pos="0.0585908 1.47606 1.06068" quat="0.707107 0 0 0.707107" type="box"/>
            <geom size="0.008 0.277359 1.06384" pos="0.274012 1.78508 1.16239" quat="0.707107 0 0 0.707107" type="box"/>
            <geom size="0.008 0.277359 1.06384" pos="0.274012 2.16903 1.16239" quat="0.707107 0 0 0.707107" type="box"/>
            <geom size="0.183882 0.277359 0.008" pos="0.274012 1.97705 2.21823" quat="0.707107 0 0 0.707107" type="box"/>
            <geom size="0.183882 0.277359 0.008" pos="0.274012 1.97705 2.13823" quat="0.707107 0 0 0.707107" type="box"/>
            <geom size="0.183882 0.277359 0.008" pos="0.274012 1.97705 0.106449" quat="0.707107 0 0 0.707107" type="box"/>
            <geom size="0.183882 0.007187 0.031996" pos="0.540299 1.97705 2.17823" quat="0.707107 0 0 0.707107" type="box"/>
            <geom size="0.183882 0.004 1.04784" pos="0.0125374 1.97705 1.16239" quat="0.707107 0 0 0.707107" type="box"/>
            <geom size="0.01 0.277193 1.06382" pos="0.27183 2.77187 1.16288" quat="0.707107 0 0 0.707107" type="box"/>
            <geom size="0.01 0.277193 1.06382" pos="0.27183 2.18793 1.16288" quat="0.707107 0 0 0.707107" type="box"/>
            <geom size="0.286067 0.277193 0.008" pos="0.27183 2.4799 2.21872" quat="0.707107 0 0 0.707107" type="box"/>
            <geom size="0.286067 0.277193 0.008" pos="0.27183 2.4799 2.05873" quat="0.707107 0 0 0.707107" type="box"/>
            <geom size="0.286067 0.277193 0.008" pos="0.27183 2.4799 1.98274" quat="0.707107 0 0 0.707107" type="box"/>
            <geom size="0.286067 0.277193 0.008" pos="0.27183 2.4799 0.181936" quat="0.707107 0 0 0.707107" type="box"/>
            <geom size="0.286067 0.277193 0.008" pos="0.27183 2.4799 0.106939" quat="0.707107 0 0 0.707107" type="box"/>
            <geom size="0.286067 0.0104594 0.07201" pos="0.537438 2.4799 2.1387" quat="0.707107 0 0 0.707107" type="box"/>
            <geom size="0.286067 0.0104594 0.03" pos="0.537438 2.4799 2.02068" quat="0.707107 0 0 0.707107" type="box"/>
            <geom size="0.286067 0.0104594 0.03" pos="0.537438 2.4799 2.02068" quat="0.707107 0 0 0.707107" type="box"/>
            <geom size="0.073992 0.008 0.037346" pos="0.53947 2.68778 0.136589" quat="0.707107 0 0 0.707107" type="box"/>
            <geom size="0.021622 0.241826 0.879405" pos="0.278115 2.7406 1.08119" quat="0.707107 0 0 0.707107" type="box"/>
            <geom size="0.021622 0.241826 0.879405" pos="0.278115 2.22505 1.08119" quat="0.707107 0 0 0.707107" type="box"/>
            <geom size="0.012277 0.196424 0.318196" pos="0.323517 2.70606 0.520043" quat="0.707107 0 0 0.707107" type="box"/>
            <geom size="0.012277 0.196424 0.318196" pos="0.323517 2.25959 0.520043" quat="0.707107 0 0 0.707107" type="box"/>
            <geom size="0.278217 0.246695 0.023998" pos="0.283132 2.48282 1.93659" quat="0.707107 0 0 0.707107" type="box"/>
            <geom size="0.234783 0.196424 0.03771" pos="0.323517 2.48282 1.92088" quat="0.707107 0 0 0.707107" type="box"/>
            <geom size="0.234783 0.196424 0.0125" pos="0.323517 2.48282 1.30616" quat="0.707107 0 0 0.707107" type="box"/>
            <geom size="0.234783 0.196424 0.058965" pos="0.323517 2.48282 0.897205" quat="0.707107 0 0 0.707107" type="box"/>
            <geom size="0.234783 0.196424 0.036788" pos="0.323517 2.48282 0.238568" quat="0.707107 0 0 0.707107" type="box"/>
            <geom size="0.234783 0.00782 0.464658" pos="0.134802 2.48282 1.42094" quat="0.707107 0 0 0.707107" type="box"/>
            <geom size="0.234783 0.058398 0.281275" pos="0.0943883 2.48282 0.556964" quat="0.707107 0 0 0.707107" type="box"/>
            <geom size="0.234134 0.133991 0.004544" pos="0.295194 2.48078 1.62664" quat="0.707107 0 0 0.707107" type="box"/>
            <geom size="0.234134 0.133991 0.004544" pos="0.295194 2.48078 1.49242" quat="0.707107 0 0 0.707107" type="box"/>
            <geom size="0.483948 0.005 0.38291" pos="0.0132597 3.28383 1.82711" quat="0.707107 0 0 0.707107" type="box"/>
            <geom size="0.008 0.174981 0.398908" pos="0.172244 2.79198 1.82711" quat="0.707107 0 0 0.707107" type="box"/>
            <geom size="0.008 0.174981 0.398908" pos="0.172244 3.77588 1.82711" quat="0.707107 0 0 0.707107" type="box"/>
            <geom size="0.01 0.184869 0.398908" pos="0.182244 3.79388 1.82711" quat="0.707107 0 0 0.707107" type="box"/>
            <geom size="0.483948 0.168981 0.008" pos="0.178244 3.28383 2.21802" quat="0.707107 0 0 0.707107" type="box"/>
            <geom size="0.483948 0.168981 0.008" pos="0.178244 3.28383 1.43611" quat="0.707107 0 0 0.707107" type="box"/>
            <geom size="0.497446 0.0095 0.197868" pos="0.3574 3.28551 2.02628" quat="0.707107 0 0 0.707107" type="box"/>
            <geom size="0.497446 0.0095 0.197868" pos="0.358032 3.28457 1.62717" quat="0.707107 0 0 0.707107" type="box"/>
            <geom size="0.01 0.0065 0.0065" pos="0.377602 3.21872 1.49359" quat="0 0 0 1" type="box"/>
            <geom size="0.01 0.0065 0.0065" pos="0.377602 3.37872 1.49359" quat="0 0 0 1" type="box"/>
            <geom size="0.0065 0.086516 0.0065" pos="0.394101 3.29872 1.49359" quat="0 0 0 1" type="box"/>
            <geom size="0.483948 0.153539 0.004042" pos="0.173906 3.28372 1.95212" quat="-0.707107 0 0 0.707107" type="box"/>
            <geom size="0.483948 0.153539 0.004042" pos="0.173906 3.28372 1.72871" quat="-0.707107 0 0 0.707107" type="box"/>
            <geom size="0.515532 0.2995 0.013389" pos="0.281428 3.29494 0.908921" quat="0.707107 0 0 -0.707107" type="box"/>
            <geom size="0.008 0.27726 0.399006" pos="0.274766 2.79215 0.494207" quat="0.707107 0 0 0.707107" type="box"/>
            <geom size="0.008 0.27726 0.399006" pos="0.274766 3.37608 0.494207" quat="0.707107 0 0 0.707107" type="box"/>
            <geom size="0.284067 0.27726 0.008" pos="0.274766 3.08412 0.103201" quat="0.707107 0 0 0.707107" type="box"/>
            <geom size="0.284067 0.04 0.008" pos="0.0572901 3.08412 0.885116" quat="0.707107 0 0 0.707107" type="box"/>
            <geom size="0.284067 0.004 0.38291" pos="0.0132931 3.08412 0.494207" quat="0.707107 0 0 0.707107" type="box"/>
            <geom size="0.008 0.27726 0.399006" pos="0.274766 3.39206 0.494207" quat="0.707107 0 0 0.707107" type="box"/>
            <geom size="0.008 0.27726 0.399006" pos="0.274766 3.77562 0.494207" quat="0.707107 0 0 0.707107" type="box"/>
            <geom size="0.184833 0.27726 0.008" pos="0.274766 3.58384 0.103201" quat="0.707107 0 0 0.707107" type="box"/>
            <geom size="0.184833 0.04 0.008" pos="0.0572901 3.58384 0.885116" quat="0.707107 0 0 0.707107" type="box"/>
            <geom size="0.184833 0.004 0.38291" pos="0.0132931 3.58384 0.494207" quat="0.707107 0 0 0.707107" type="box"/>
            <geom size="0.009554 0.296074 0.448506" pos="0.272592 3.79516 0.446017" quat="0.707107 0 0 0.707107" type="box"/>
            <geom size="1.30158 0.009889 0.05" pos="0.55976 2.47826 0.0516843" quat="0.707107 0 0 -0.707107" type="box"/>
            <geom size="0.0145 0.5 0.467231" pos="2.75274 1.13354 0.465629" quat="0.707107 0 0 -0.707107" type="box"/>
            <geom size="1.58852 0.237531 0.015" pos="3.01571 2.70904 0.919266" quat="0.707107 0 0 -0.707107" type="box"/>
            <geom size="1.58852 0.048817 0.015" pos="2.30169 2.70904 0.919266" quat="0.707107 0 0 -0.707107" type="box"/>
            <geom size="0.367711 0.498 0.015" pos="2.75274 3.93117 0.919266" quat="0.707107 0 0 -0.707107" type="box"/>
            <geom size="1.02804 0.498 0.015" pos="2.75274 2.14849 0.919266" quat="0.707107 0 0 -0.707107" type="box"/>
            <geom size="0.3975 0.258 0.002401" pos="2.59619 1.62758 0.937235" quat="0.707107 0 0 -0.707107" type="box"/>
            <geom size="0.202106 0.038996 0.088694" pos="2.74735 3.37457 0.848034" quat="0.707107 0 0 -0.707107" type="box"/>
            <geom size="0.202106 0.01 0.088694" pos="2.35139 3.37457 0.848034" quat="0.707107 0 0 -0.707107" type="box"/>
            <geom size="0.01 0.222309 0.088694" pos="2.56387 3.18209 0.848034" quat="0.707107 0 0 -0.707107" type="box"/>
            <geom size="0.01 0.222309 0.088694" pos="2.56387 3.56705 0.848034" quat="0.707107 0 0 -0.707107" type="box"/>
            <geom size="0.202106 0.222309 0.013701" pos="2.56387 3.37457 0.773042" quat="0.707107 0 0 -0.707107" type="box"/>
            <geom size="0.022435 0.038739" pos="2.75434 3.37446 0.975401" quat="0.707107 0 0 -0.707107" type="cylinder"/>
            <geom size="0.014 0.10908" pos="2.75434 3.37446 1.12843" quat="0.707107 0 0 -0.707107" type="cylinder"/>
            <geom size="0.010966 0.003818" pos="2.5244 3.37446 1.20835" quat="0.707107 0 0 -0.707107" type="cylinder"/>
            <geom size="0.022466 0.044495" pos="2.75437 3.36396 1.0135" quat="0.5 0.5 0.5 -0.5" type="cylinder"/>
            <geom size="0.018" pos="2.75438 3.31946 1.01353" quat="0.707107 0 0 -0.707107"/>
            <geom size="0.014 0.131986" pos="2.63639 3.37445 1.22351" quat="0.5 0.5 -0.5 -0.5" type="cylinder"/>
            <geom size="0.007724 0.197879 0.420898" pos="2.66833 4.25475 0.420114" quat="0.707107 0 0 -0.707107" type="box"/>
            <geom size="0.007724 0.197879 0.420898" pos="2.66833 3.67236 0.420114" quat="0.707107 0 0 -0.707107" type="box"/>
            <geom size="0.007724 0.064761 0.351941" pos="2.40569 4.25475 0.49107" quat="0.707107 0 0 -0.707107" type="box"/>
            <geom size="0.007724 0.064761 0.351941" pos="2.40569 3.67236 0.49107" quat="0.707107 0 0 -0.707107" type="box"/>
            <geom size="0.298917 0.002413 0.420898" pos="2.86375 3.96355 0.420114" quat="0.707107 0 0 -0.707107" type="box"/>
            <geom size="0.298917 0.258487 0.006749" pos="2.60766 3.96355 0.834262" quat="0.707107 0 0 -0.707107" type="box"/>
            <geom size="0.298917 0.258487 0.083552" pos="2.60766 3.96355 0.0826564" quat="0.707107 0 0 -0.707107" type="box"/>
            <geom size="0.007942 0.277025 0.398895" pos="2.59268 3.66423 0.494481" quat="0.707107 0 0 -0.707107" type="box"/>
            <geom size="0.007942 0.277025 0.398895" pos="2.59268 3.08041 0.494481" quat="0.707107 0 0 -0.707107" type="box"/>
            <geom size="0.284067 0.003944 0.382909" pos="2.85421 3.37232 0.494481" quat="0.707107 0 0 -0.707107" type="box"/>
            <geom size="0.284067 0.04 0.008" pos="2.81016 3.37232 0.885391" quat="0.707107 0 0 -0.707107" type="box"/>
            <geom size="0.284067 0.277025 0.008" pos="2.59268 3.37232 0.103476" quat="0.707107 0 0 -0.707107" type="box"/>
            <geom size="0.007942 0.277025 0.398895" pos="2.59288 3.0646 0.494068" quat="0.707107 0 0 -0.707107" type="box"/>
            <geom size="0.007942 0.277025 0.398895" pos="2.59288 2.48078 0.494068" quat="0.707107 0 0 -0.707107" type="box"/>
            <geom size="0.284067 0.003944 0.382909" pos="2.85441 2.77269 0.494068" quat="0.707107 0 0 -0.707107" type="box"/>
            <geom size="0.284067 0.04 0.008" pos="2.81036 2.77269 0.884978" quat="0.707107 0 0 -0.707107" type="box"/>
            <geom size="0.284067 0.277025 0.008" pos="2.59288 2.77269 0.103063" quat="0.707107 0 0 -0.707107" type="box"/>
            <geom size="0.008 0.27726 0.399006" pos="2.59299 2.4637 0.50112" quat="0.707107 0 0 -0.707107" type="box"/>
            <geom size="0.008 0.27726 0.399006" pos="2.59299 2.08014 0.50112" quat="0.707107 0 0 -0.707107" type="box"/>
            <geom size="0.184833 0.27726 0.008" pos="2.59299 2.27192 0.110114" quat="0.707107 0 0 -0.707107" type="box"/>
            <geom size="0.184833 0.04 0.008" pos="2.81047 2.27192 0.892029" quat="0.707107 0 0 -0.707107" type="box"/>
            <geom size="0.184833 0.004 0.38291" pos="2.85446 2.27192 0.50112" quat="0.707107 0 0 -0.707107" type="box"/>
            <geom size="0.008 0.27726 0.399006" pos="2.59294 2.06351 0.509844" quat="0.707107 0 0 -0.707107" type="box"/>
            <geom size="0.008 0.27726 0.399006" pos="2.59294 1.17961 0.509844" quat="0.707107 0 0 -0.707107" type="box"/>
            <geom size="0.43394 0.27726 0.008" pos="2.59294 1.62156 0.118838" quat="0.707107 0 0 -0.707107" type="box"/>
            <geom size="0.43394 0.04 0.008" pos="2.81041 1.62156 0.900753" quat="0.707107 0 0 -0.707107" type="box"/>
            <geom size="0.43394 0.004 0.38291" pos="2.85441 1.62156 0.509844" quat="0.707107 0 0 -0.707107" type="box"/>
            <geom size="1.55624 0.01 0.05" pos="2.31094 2.71198 0.0496364" quat="0.707107 0 0 -0.707107" type="box"/>
            <geom size="1.56783 0.009625 0.451805" pos="2.96825 2.7196 0.450317" quat="0.707107 0 0 -0.707107" type="box"/>
            <geom size="0.01 0.339444 0.451805" pos="2.63831 4.2773 0.45176" quat="0.707107 0 0 0.707107" type="box"/>
            <geom size="0.01 0.339444 0.451805" pos="2.6375 1.16089 0.446014" quat="0.707107 0 0 0.707107" type="box"/>
            <body name="window4_right" pos="10.4376 5.12273 1.09598" gravcomp="0">
                <joint name="window4_right_joint" pos="0 0 0" axis="0 0 1" range="0 1.5708"/>
                <geom size="0.421713 0.01 1.03155" pos="-0.421713 0 0" type="box"/>
                <body name="window4_right_handle" pos="-0.815383 -0.019236 0" gravcomp="0">
                    <joint name="window4_right_handle_joint" pos="0 0 0" axis="0 -1 0" range="0 3.14159"/>
                    <geom size="0.008 0.037618" pos="0 -0.011369 0" quat="0.707107 0.707107 0 0" type="cylinder"/>
                    <geom size="0.008 0.065813" pos="0 -0.040987 -0.057684" type="cylinder"/>
                    <geom size="0.008 0.026476" pos="0 -0.022511 -0.115497" quat="0.707107 0.707107 0 0" type="cylinder"/>
                </body>
            </body>
            <body name="window4_left" pos="8.59199 5.12435 1.09598" gravcomp="0">
                <joint name="window4_left_joint" pos="0 0 0" axis="0 0 -1" range="0 1.5708"/>
                <geom size="0.43203 0.01 1.03155" pos="0.43203 0 0" type="box"/>
                <body name="window4_left_handle" pos="0.834107 -0.019236 0" gravcomp="0">
                    <joint name="window4_left_handle_joint" pos="0 0 0" axis="0 -1 0" range="0 3.14159"/>
                    <geom size="0.008 0.037618" pos="0 -0.011369 0" quat="0.707107 0.707107 0 0" type="cylinder"/>
                    <geom size="0.008 0.065813" pos="0 -0.040987 -0.057684" type="cylinder"/>
                    <geom size="0.008 0.026476" pos="0 -0.022511 -0.115497" quat="0.707107 0.707107 0 0" type="cylinder"/>
                </body>
            </body>
            <body name="wardrobe_door_left" pos="18.2336 1.6169 0" gravcomp="0">
                <joint name="wardrobe_door_left_joint" pos="0 0 0" axis="0 0 -1" range="0 1.5708"/>
                <geom size="0.0064835 0.247719 0.82422" pos="-0.006435 -0.2485 0.975" type="box"/>
                <geom size="0.016778 0.007541 0.0072935" pos="-0.021668 -0.460513 1.03271" type="box"/>
                <geom size="0.007243 0.007541 0.065" pos="-0.045689 -0.460513 0.973703" type="box"/>
                <geom size="0.016778 0.007541 0.0072935" pos="-0.021668 -0.460513 0.9147" type="box"/>
            </body>
            <body name="wardrobe_door_right" pos="18.2336 0.6169 0" gravcomp="0">
                <joint name="wardrobe_door_right_joint" pos="0 0 0" axis="0 0 1" range="0 1.5708"/>
                <geom size="0.0064835 0.247719 0.82422" pos="-0.006435 0.2485 0.975" type="box"/>
                <geom size="0.016778 0.007541 0.0072935" pos="-0.021668 0.460513 1.03271" type="box"/>
                <geom size="0.007243 0.007541 0.065" pos="-0.045689 0.460513 0.973703" type="box"/>
                <geom size="0.016778 0.007541 0.0072935" pos="-0.021668 0.460513 0.9147" type="box"/>
            </body>
            <body name="coffee_table_drawer" pos="16.6534 2.77957 0" quat="0.707105 0 0 0.707108" gravcomp="0">
                <joint name="coffee_table_drawer_joint" pos="0 0 0" axis="-1 0 0" type="slide" range="0 0.5"/>
                <geom size="0.0107 0.198 0.157845" pos="-0.338806 0 0.21892" type="box"/>
                <geom size="0.27605 0.1727 0.01072" pos="-0.051066 0 0.107979" type="box"/>
                <geom size="0.0107 0.1743 0.1199" pos="0.207974 0 0.238907" type="box"/>
                <geom size="0.27605 0.0107 0.132125" pos="-0.051066 -0.186206 0.226597" type="box"/>
                <geom size="0.27605 0.0107 0.132125" pos="-0.051066 0.186206 0.226597" type="box"/>
            </body>
            <body name="cabinet1_door" pos="0.564632 1.18676 1.79141" quat="0.707107 0 0 0.707107" gravcomp="0">
                <joint name="cabinet1_door_joint" pos="0 0 0" axis="0 0 -1" range="0 1.5708"/>
                <geom size="0.298468 0.0095 0.433405" pos="0.285091 0 0" type="box"/>
                <geom size="0.01 0.0065 0.0065" pos="0.383156 -0.0194908 -0.389834" quat="0.707107 0 0 0.707107" type="box"/>
                <geom size="0.01 0.0065 0.0065" pos="0.543156 -0.0194908 -0.389834" quat="0.707107 0 0 0.707107" type="box"/>
                <geom size="0.0065 0.086516 0.0065" pos="0.463156 -0.0359893 -0.389834" quat="0.707107 0 0 0.707107" type="box"/>
            </body>
            <body name="cabinet1_drawer1" pos="0.331422 1.47798 0.627821" quat="0.707107 0 0 0.707107" gravcomp="0">
                <joint name="cabinet1_drawer1_joint" pos="0 0 0" axis="0 -1 0" type="slide" range="0 0.45"/>
                <geom size="0.298468 0.0095 0.131486" pos="0 -0.233977 0" type="box"/>
                <geom size="0.0079221 0.24585 0.0111962" pos="0.26865 0.021336 0.0412455" type="box"/>
                <geom size="0.0079221 0.24585 0.0111962" pos="-0.26865 0.021336 0.0412455" type="box"/>
                <geom size="0.0079221 0.24585 0.041748" pos="0.26865 0.021336 -0.078968" type="box"/>
                <geom size="0.0079221 0.24585 0.026549" pos="-0.26865 0.021336 -0.0941" type="box"/>
                <geom size="0.26182 0.24578 0.008" pos="0 0.021399 -0.114232" type="box"/>
                <geom size="0.26182 0.00932692 0.084435" pos="0 0.26 -0.038" type="box"/>
                <geom size="0.01 0.0065 0.0065" pos="-0.0790818 -0.25182 0.0840143" quat="0.707107 0 0 0.707107" type="box"/>
                <geom size="0.01 0.0065 0.0065" pos="0.0809182 -0.25182 0.0840143" quat="0.707107 0 0 0.707107" type="box"/>
                <geom size="0.0065 0.086516 0.0065" pos="0.00091816 -0.268319 0.0840143" quat="0.707107 0 0 0.707107" type="box"/>
            </body>
            <body name="cabinet1_drawer2" pos="0.330632 1.47776 0.298406" quat="0.707107 0 0 0.707107" gravcomp="0">
                <joint name="cabinet1_drawer2_joint" pos="0 0 0" axis="0 -1 0" type="slide" range="0 0.45"/>
                <geom size="0.298468 0.0095 0.19714" pos="0 -0.233977 0" type="box"/>
                <geom size="0.0079221 0.24585 0.0111962" pos="0.26865 0.021336 -0.0084109" type="box"/>
                <geom size="0.0079221 0.24585 0.0111962" pos="-0.26865 0.021336 -0.0084109" type="box"/>
                <geom size="0.0079221 0.24585 0.041751" pos="0.26865 0.021336 -0.12854" type="box"/>
                <geom size="0.0079221 0.24585 0.041751" pos="-0.26865 0.021336 -0.12854" type="box"/>
                <geom size="0.26182 0.24578 0.008" pos="0 0.021399 -0.16226" type="box"/>
                <geom size="0.26182 0.00932692 0.0758612" pos="0 0.26 -0.0797358" type="box"/>
                <geom size="0.01 0.0065 0.0065" pos="-0.0785416 -0.252985 0.150606" quat="0.707107 0 0 0.707107" type="box"/>
                <geom size="0.01 0.0065 0.0065" pos="0.0814585 -0.252985 0.150606" quat="0.707107 0 0 0.707107" type="box"/>
                <geom size="0.0065 0.086516 0.0065" pos="0.00145845 -0.269484 0.150606" quat="0.707107 0 0 0.707107" type="box"/>
            </body>
            <body name="oven_door" pos="0.558591 1.47912 0.771734" quat="0.707107 0 0 0.707107" gravcomp="0">
                <joint name="oven_door_joint" pos="0 0 0" axis="1 0 0" range="0 1.5708"/>
                <geom size="0.295294 0.018499 0.235848" pos="-0.002993 0.005395 0.226757" type="box"/>
            </body>
            <body name="cabinet2_door" pos="0.564231 1.79048 1.16345" quat="0.707107 0 0 0.707107" gravcomp="0">
                <joint name="cabinet2_door_joint" pos="0 0 0" axis="0 0 -1" range="0 1.5708"/>
                <geom size="0.198479 0.0095 1.06138" pos="0.185074 -0.000653 0" type="box"/>
                <geom size="0.01 0.0065 0.0065" pos="0.17886 -0.00574094 -0.105189" quat="0.707107 0 0 0.707107" type="box"/>
                <geom size="0.01 0.0065 0.0065" pos="0.33886 -0.00574094 -0.105189" quat="0.707107 0 0 0.707107" type="box"/>
                <geom size="0.0065 0.086516 0.0065" pos="0.25886 -0.0222394 -0.105189" quat="0.707107 0 0 0.707107" type="box"/>
            </body>
            <body name="cabinet2_drawer1" pos="0.284557 1.9784 1.74285" quat="0.707107 0 0 0.707107" gravcomp="0">
                <joint name="cabinet2_drawer1_joint" pos="0 0 0" axis="0 -1 0" type="slide" range="0 0.45"/>
                <geom size="0.180981 0.0085 0.050495" pos="0 -0.242975 0" type="box"/>
                <geom size="0.180981 0.008064 0.050495" pos="0 0.235441 0" type="box"/>
                <geom size="0.008 0.247489 0.050495" pos="-0.170578 -0.003984 0" type="box"/>
                <geom size="0.008 0.247489 0.050495" pos="0.170578 -0.003984 0" type="box"/>
                <geom size="0.180981 0.247489 0.010749" pos="0 -0.003984 -0.039746" type="box"/>
            </body>
            <body name="cabinet2_drawer2" pos="0.284557 1.9784 1.58514" quat="0.707107 0 0 0.707107" gravcomp="0">
                <joint name="cabinet2_drawer2_joint" pos="0 0 0" axis="0 -1 0" type="slide" range="0 0.45"/>
                <geom size="0.180981 0.006898 0.049" pos="0 -0.242374 -0.042" type="box"/>
                <geom size="0.180981 0.006898 0.010149" pos="0 -0.242374 0.060843" type="box"/>
                <geom size="0.032441 0.008393 0.09099" pos="-0.148428 -0.242869 0" type="box"/>
                <geom size="0.032441 0.008393 0.09099" pos="0.148428 -0.242869 0" type="box"/>
                <geom size="0.180981 0.008064 0.090879" pos="0 0.235441 0" type="box"/>
                <geom size="0.008 0.247489 0.011649" pos="-0.170578 -0.003984 0.075342" type="box"/>
                <geom size="0.008 0.247489 0.011649" pos="0.170578 -0.003984 0.075342" type="box"/>
                <geom size="0.008 0.247489 0.043553" pos="-0.170578 -0.003984 -0.043743" type="box"/>
                <geom size="0.008 0.247489 0.043553" pos="0.170578 -0.003984 -0.043743" type="box"/>
                <geom size="0.180981 0.247489 0.010749" pos="0 -0.003984 -0.080242" type="box"/>
            </body>
            <body name="cabinet2_drawer3" pos="0.284557 1.9784 1.30529" quat="0.707107 0 0 0.707107" gravcomp="0">
                <joint name="cabinet2_drawer3_joint" pos="0 0 0" axis="0 -1 0" type="slide" range="0 0.45"/>
                <geom size="0.180981 0.006898 0.049" pos="0 -0.242374 -0.042" type="box"/>
                <geom size="0.180981 0.006898 0.010149" pos="0 -0.242374 0.060843" type="box"/>
                <geom size="0.032441 0.008393 0.09099" pos="-0.148428 -0.242869 0" type="box"/>
                <geom size="0.032441 0.008393 0.09099" pos="0.148428 -0.242869 0" type="box"/>
                <geom size="0.180981 0.008064 0.090879" pos="0 0.235441 0" type="box"/>
                <geom size="0.008 0.247489 0.011649" pos="-0.170578 -0.003984 0.075342" type="box"/>
                <geom size="0.008 0.247489 0.011649" pos="0.170578 -0.003984 0.075342" type="box"/>
                <geom size="0.008 0.247489 0.043553" pos="-0.170578 -0.003984 -0.043743" type="box"/>
                <geom size="0.008 0.247489 0.043553" pos="0.170578 -0.003984 -0.043743" type="box"/>
                <geom size="0.180981 0.247489 0.010749" pos="0 -0.003984 -0.080242" type="box"/>
            </body>
            <body name="cabinet2_drawer4" pos="0.284557 1.9784 0.919952" quat="0.707107 0 0 0.707107" gravcomp="0">
                <joint name="cabinet2_drawer4_joint" pos="0 0 0" axis="0 -1 0" type="slide" range="0 0.45"/>
                <geom size="0.180981 0.006898 0.049" pos="0 -0.242374 -0.042" type="box"/>
                <geom size="0.180981 0.006898 0.010149" pos="0 -0.242374 0.060843" type="box"/>
                <geom size="0.032441 0.008393 0.09099" pos="-0.148428 -0.242869 0" type="box"/>
                <geom size="0.032441 0.008393 0.09099" pos="0.148428 -0.242869 0" type="box"/>
                <geom size="0.180981 0.008064 0.090879" pos="0 0.235441 0" type="box"/>
                <geom size="0.008 0.247489 0.011649" pos="-0.170578 -0.003984 0.075342" type="box"/>
                <geom size="0.008 0.247489 0.011649" pos="0.170578 -0.003984 0.075342" type="box"/>
                <geom size="0.008 0.247489 0.043553" pos="-0.170578 -0.003984 -0.043743" type="box"/>
                <geom size="0.008 0.247489 0.043553" pos="0.170578 -0.003984 -0.043743" type="box"/>
                <geom size="0.180981 0.247489 0.010749" pos="0 -0.003984 -0.080242" type="box"/>
            </body>
            <body name="cabinet2_drawer5" pos="0.284557 1.9784 0.644293" quat="0.707107 0 0 0.707107" gravcomp="0">
                <joint name="cabinet2_drawer5_joint" pos="0 0 0" axis="0 -1 0" type="slide" range="0 0.45"/>
                <geom size="0.180981 0.006898 0.049" pos="0 -0.242374 -0.042" type="box"/>
                <geom size="0.180981 0.006898 0.010149" pos="0 -0.242374 0.060843" type="box"/>
                <geom size="0.032441 0.008393 0.09099" pos="-0.148428 -0.242869 0" type="box"/>
                <geom size="0.032441 0.008393 0.09099" pos="0.148428 -0.242869 0" type="box"/>
                <geom size="0.180981 0.008064 0.090879" pos="0 0.235441 0" type="box"/>
                <geom size="0.008 0.247489 0.011649" pos="-0.170578 -0.003984 0.075342" type="box"/>
                <geom size="0.008 0.247489 0.011649" pos="0.170578 -0.003984 0.075342" type="box"/>
                <geom size="0.008 0.247489 0.043553" pos="-0.170578 -0.003984 -0.043743" type="box"/>
                <geom size="0.008 0.247489 0.043553" pos="0.170578 -0.003984 -0.043743" type="box"/>
                <geom size="0.180981 0.247489 0.010749" pos="0 -0.003984 -0.080242" type="box"/>
            </body>
            <body name="cabinet2_drawer6" pos="0.284557 1.9784 0.207197" quat="0.707107 0 0 0.707107" gravcomp="0">
                <joint name="cabinet2_drawer6_joint" pos="0 0 0" axis="0 -1 0" type="slide" range="0 0.45"/>
                <geom size="0.180981 0.006898 0.049" pos="0 -0.242374 -0.042" type="box"/>
                <geom size="0.180981 0.006898 0.010149" pos="0 -0.242374 0.060843" type="box"/>
                <geom size="0.032441 0.008393 0.09099" pos="-0.148428 -0.242869 0" type="box"/>
                <geom size="0.032441 0.008393 0.09099" pos="0.148428 -0.242869 0" type="box"/>
                <geom size="0.180981 0.008064 0.090879" pos="0 0.235441 0" type="box"/>
                <geom size="0.008 0.247489 0.011649" pos="-0.170578 -0.003984 0.075342" type="box"/>
                <geom size="0.008 0.247489 0.011649" pos="0.170578 -0.003984 0.075342" type="box"/>
                <geom size="0.008 0.247489 0.043553" pos="-0.170578 -0.003984 -0.043743" type="box"/>
                <geom size="0.008 0.247489 0.043553" pos="0.170578 -0.003984 -0.043743" type="box"/>
                <geom size="0.180981 0.247489 0.010749" pos="0 -0.003984 -0.080242" type="box"/>
            </body>
            <body name="fridge_door1" pos="0.572244 2.18075 1.41962" quat="0.707107 0 0 0.707107" gravcomp="0">
                <joint name="fridge_door1_joint" pos="0 0 0" axis="0 0 -1" range="0 1.5708"/>
                <geom size="0.298246 0.009277 0.668339" pos="0.297325 0.006948 0.139709" type="box"/>
                <geom size="0.276867 0.0125 0.494447" pos="0.295455 0.03605 -0.001115" type="box"/>
                <geom size="0.01 0.0065 0.0065" pos="0.385343 -0.011882 -0.3616" quat="0.707107 0 0 0.707107" type="box"/>
                <geom size="0.01 0.0065 0.0065" pos="0.545343 -0.011882 -0.3616" quat="0.707107 0 0 0.707107" type="box"/>
                <geom size="0.0065 0.086516 0.0065" pos="0.465343 -0.0283805 -0.3616" quat="0.707107 0 0 0.707107" type="box"/>
                <geom size="0.001 0.210927 0.047787" pos="0.297261 0.158064 -0.0156525" quat="0.707107 0 0 0.707107" type="box"/>
                <geom size="0.001 0.210927 0.047787" pos="0.297261 0.0495177 -0.0156525" quat="0.707107 0 0 0.707107" type="box"/>
                <geom size="0.05471 0.001 0.047787" pos="0.0872828 0.103791 -0.0156525" quat="0.707107 0 0 0.707107" type="box"/>
                <geom size="0.05471 0.001 0.047787" pos="0.507239 0.103791 -0.0156525" quat="0.707107 0 0 0.707107" type="box"/>
                <geom size="0.05471 0.210927 0.001" pos="0.297261 0.103791 -0.0628185" quat="0.707107 0 0 0.707107" type="box"/>
                <geom size="0.001 0.210977 0.026901" pos="0.298471 0.155788 0.223872" quat="0.707107 0 0 0.707107" type="box"/>
                <geom size="0.001 0.210977 0.026901" pos="0.298471 0.0477503 0.223872" quat="0.707107 0 0 0.707107" type="box"/>
                <geom size="0.054994 0.001 0.026901" pos="0.0884929 0.101769 0.223872" quat="0.707107 0 0 0.707107" type="box"/>
                <geom size="0.054994 0.001 0.026901" pos="0.508449 0.101769 0.223872" quat="0.707107 0 0 0.707107" type="box"/>
                <geom size="0.054994 0.210977 0.001" pos="0.298471 0.101769 0.197969" quat="0.707107 0 0 0.707107" type="box"/>
                <geom pos="0.213162 0.0995036 0.224571" quat="0.707107 0 0 0.707107" type="mesh" mesh="SM_Fridge_Egg_Tray"/>
            </body>
            <body name="fridge_door2" pos="0.572244 2.18081 0.524871" quat="0.707107 0 0 0.707107" gravcomp="0">
                <joint name="fridge_door2_joint" pos="0 0 0" axis="0 0 -1" range="0 1.5708"/>
                <geom size="0.298246 0.009277 0.39297" pos="0.297325 0.006948 -0.028308" type="box"/>
                <geom size="0.276867 0.0125 0.311166" pos="0.295455 0.03605 0.019366" type="box"/>
                <geom size="0.01 0.0065 0.0065" pos="0.385383 0.00415557 0.317868" quat="0.707107 0 0 0.707107" type="box"/>
                <geom size="0.01 0.0065 0.0065" pos="0.545383 0.00415557 0.317868" quat="0.707107 0 0 0.707107" type="box"/>
                <geom size="0.0065 0.086516 0.0065" pos="0.465383 -0.0123429 0.317868" quat="0.707107 0 0 0.707107" type="box"/>
            </body>
            <body name="fridge_drawer1" pos="0.306256 2.48059 1.19144" quat="0.707107 0 0 0.707107" gravcomp="0">
                <joint name="fridge_drawer1_joint" pos="0 0 0" axis="0 -1 0" type="slide" range="0 0.3"/>
                <geom size="0.227117 0.0025 0.011921" pos="0 -0.169309 0.070506" type="box"/>
                <geom size="0.227117 0.001448 0.047864" pos="0 -0.169309 -0.034598" type="box"/>
                <geom size="0.227117 0.002123 0.082076" pos="0 0.16468 0" type="box"/>
                <geom size="0.00983 0.171761 0.082076" pos="-0.217307 0 0" type="box"/>
                <geom size="0.00983 0.171761 0.082076" pos="0.217307 0 0" type="box"/>
                <geom size="0.227117 0.171761 0.001372" pos="0 0 -0.080999" type="box"/>
            </body>
            <body name="fridge_drawer2" pos="0.30965 2.48481 1.03157" quat="0.707107 0 0 0.707107" gravcomp="0">
                <joint name="fridge_drawer2_joint" pos="0 0 0" axis="0 -1 0" type="slide" range="0 0.3"/>
                <geom size="0.227117 0.0025 0.011801" pos="0 -0.169309 0.057007" type="box"/>
                <geom size="0.227117 0.001448 0.032111" pos="0 -0.169309 -0.036775" type="box"/>
                <geom size="0.227117 0.002123 0.068941" pos="0 0.16468 0" type="box"/>
                <geom size="0.00983 0.171761 0.068941" pos="-0.217307 0 0" type="box"/>
                <geom size="0.00983 0.171761 0.068941" pos="0.217307 0 0" type="box"/>
                <geom size="0.227117 0.171761 0.001372" pos="0 0 -0.066161" type="box"/>
            </body>
            <body name="fridge_drawer3" pos="0.326823 2.4803 0.725009" quat="0.707107 0 0 0.707107" gravcomp="0">
                <joint name="fridge_drawer3_joint" pos="0 0 0" axis="0 -1 0" type="slide" range="0 0.3"/>
                <geom size="0.204478 0.001 0.012462" pos="0 -0.165482 0.083453" type="box"/>
                <geom size="0.204478 0.001 0.05887" pos="0 -0.165482 -0.037113" type="box"/>
                <geom size="0.204478 0.001555 0.095915" pos="0 0.154928 0" type="box"/>
                <geom size="0.00732 0.161445 0.095915" pos="-0.197083 -0.004962 0" type="box"/>
                <geom size="0.00732 0.161445 0.095915" pos="0.197083 -0.004962 0" type="box"/>
                <geom size="0.204478 0.161445 0.000911" pos="0 -0.004962 -0.095072" type="box"/>
            </body>
            <body name="fridge_drawer4" pos="0.323019 2.47774 0.548187" quat="0.707107 0 0 0.707107" gravcomp="0">
                <joint name="fridge_drawer4_joint" pos="0 0 0" axis="0 -1 0" type="slide" range="0 0.3"/>
                <geom size="0.204478 0.001 0.012462" pos="0 -0.165482 0.063456" type="box"/>
                <geom size="0.204478 0.001 0.04" pos="0 -0.165482 -0.035978" type="box"/>
                <geom size="0.204478 0.001 0.075917" pos="0 0.155483 0" type="box"/>
                <geom size="0.008 0.166408 0.075917" pos="-0.196311 0 0" type="box"/>
                <geom size="0.008 0.166408 0.075917" pos="0.196311 0 0" type="box"/>
                <geom size="0.204478 0.166408 0.001" pos="0 0 -0.074992" type="box"/>
            </body>
            <body name="fridge_drawer5" pos="0.358974 2.48282 0.368398" quat="0.707107 0 0 0.707107" gravcomp="0">
                <joint name="fridge_drawer5_joint" pos="0 0 0" axis="0 -1 0" type="slide" range="0 0.3"/>
                <geom size="0.204404 0.001 0.012499" pos="0 -0.120488 0.08099" type="box"/>
                <geom size="0.204404 0.001 0.055353" pos="0 -0.118669 -0.03813" type="box"/>
                <geom size="0.204404 0.003217 0.075917" pos="0 0.108269 0" type="box"/>
                <geom size="0.007461 0.120421 0.075917" pos="-0.196942 0 0" type="box"/>
                <geom size="0.007461 0.120421 0.075917" pos="0.196942 0 0" type="box"/>
                <geom size="0.204404 0.120421 0.001" pos="0 0 -0.09249" type="box"/>
            </body>
            <body name="cabinet5_drawer1" pos="0.327393 3.08512 0.825985" quat="0.707107 0 0 0.707107" gravcomp="0">
                <joint name="cabinet5_drawer1_joint" pos="0 0 0" axis="0 -1 0" type="slide" range="0 0.45"/>
                <geom size="0.008 0.245507 0.042633" pos="-0.270267 0.021031 -0.01336" type="box"/>
                <geom size="0.008 0.245507 0.042633" pos="0.270267 0.021031 -0.01336" type="box"/>
                <geom size="0.298468 0.0095 0.064993" pos="0 -0.233977 0" type="box"/>
                <geom size="0.269804 0.008 0.042633" pos="0 0.260372 -0.01336" type="box"/>
                <geom size="0.269804 0.245507 0.0075" pos="0 0.021031 -0.047595" type="box"/>
                <geom size="0.01 0.0065 0.0065" pos="-0.0814236 -0.2537 0.0167695" quat="0.707107 0 0 0.707107" type="box"/>
                <geom size="0.01 0.0065 0.0065" pos="0.0785764 -0.2537 0.0167695" quat="0.707107 0 0 0.707107" type="box"/>
                <geom size="0.0065 0.086516 0.0065" pos="-0.00142363 -0.270199 0.0167695" quat="0.707107 0 0 0.707107" type="box"/>
            </body>
            <body name="cabinet5_drawer2" pos="0.327804 3.08491 0.627931" quat="0.707107 0 0 0.707107" gravcomp="0">
                <joint name="cabinet5_drawer2_joint" pos="0 0 0" axis="0 -1 0" type="slide" range="0 0.45"/>
                <geom size="0.008 0.245507 0.011649" pos="-0.270267 0.021031 0.041246" type="box"/>
                <geom size="0.008 0.245507 0.011649" pos="0.270267 0.021031 0.041246" type="box"/>
                <geom size="0.008 0.245507 0.041748" pos="-0.270267 0.021031 -0.078968" type="box"/>
                <geom size="0.008 0.245507 0.041748" pos="0.270267 0.021031 -0.078968" type="box"/>
                <geom size="0.298468 0.0095 0.131375" pos="0 -0.233977 0" type="box"/>
                <geom size="0.269804 0.008 0.084491" pos="0 0.260372 -0.037996" type="box"/>
                <geom size="0.269804 0.245507 0.008" pos="0 0.021031 -0.113735" type="box"/>
                <geom size="0.01 0.0065 0.0065" pos="-0.0810641 -0.254602 0.0850084" quat="0.707107 0 0 0.707107" type="box"/>
                <geom size="0.01 0.0065 0.0065" pos="0.0789359 -0.254602 0.0850084" quat="0.707107 0 0 0.707107" type="box"/>
                <geom size="0.0065 0.086516 0.0065" pos="-0.00106413 -0.2711 0.0850084" quat="0.707107 0 0 0.707107" type="box"/>
            </body>
            <body name="cabinet5_drawer3" pos="0.328217 3.08487 0.29854" quat="0.707107 0 0 0.707107" gravcomp="0">
                <joint name="cabinet5_drawer3_joint" pos="0 0 0" axis="0 -1 0" type="slide" range="0 0.45"/>
                <geom size="0.008 0.245507 0.011638" pos="-0.270267 0.021031 -0.00926" type="box"/>
                <geom size="0.008 0.245507 0.011638" pos="0.270267 0.021031 -0.00926" type="box"/>
                <geom size="0.008 0.245507 0.041711" pos="-0.270267 0.021031 -0.129424" type="box"/>
                <geom size="0.008 0.245507 0.041711" pos="0.270267 0.021031 -0.129424" type="box"/>
                <geom size="0.298468 0.0095 0.197867" pos="0 -0.233977 0" type="box"/>
                <geom size="0.269804 0.008 0.084105" pos="0 0.260372 -0.088821" type="box"/>
                <geom size="0.269804 0.245507 0.008" pos="0 0.021031 -0.164582" type="box"/>
                <geom size="0.01 0.0065 0.0065" pos="-0.0810287 -0.252773 0.15027" quat="0.707107 0 0 0.707107" type="box"/>
                <geom size="0.01 0.0065 0.0065" pos="0.0789713 -0.252773 0.15027" quat="0.707107 0 0 0.707107" type="box"/>
                <geom size="0.0065 0.086516 0.0065" pos="-0.00102875 -0.269271 0.15027" quat="0.707107 0 0 0.707107" type="box"/>
            </body>
            <body name="cabinet6_drawer1" pos="0.328062 3.58416 0.825985" quat="0.707107 0 0 0.707107" gravcomp="0">
                <joint name="cabinet6_drawer1_joint" pos="0 0 0" axis="0 -1 0" type="slide" range="0 0.45"/>
                <geom size="0.008 0.245507 0.042633" pos="-0.170562 0.021031 -0.01336" type="box"/>
                <geom size="0.008 0.245507 0.042633" pos="0.170562 0.021031 -0.01336" type="box"/>
                <geom size="0.198867 0.0095 0.064993" pos="0 -0.233977 0" type="box"/>
                <geom size="0.178822 0.008 0.042633" pos="0 0.260372 -0.01336" type="box"/>
                <geom size="0.178822 0.245507 0.0075" pos="0 0.021031 -0.047595" type="box"/>
                <geom size="0.01 0.0065 0.0065" pos="-0.078754 -0.250514 0.0172039" quat="0.707107 0 0 0.707107" type="box"/>
                <geom size="0.01 0.0065 0.0065" pos="0.081246 -0.250514 0.0172039" quat="0.707107 0 0 0.707107" type="box"/>
                <geom size="0.0065 0.086516 0.0065" pos="0.00124599 -0.267013 0.0172039" quat="0.707107 0 0 0.707107" type="box"/>
            </body>
            <body name="cabinet6_drawer2" pos="0.327823 3.58458 0.627175" quat="0.707107 0 0 0.707107" gravcomp="0">
                <joint name="cabinet6_drawer2_joint" pos="0 0 0" axis="0 -1 0" type="slide" range="0 0.45"/>
                <geom size="0.008 0.245507 0.011649" pos="-0.170562 0.021031 0.041246" type="box"/>
                <geom size="0.008 0.245507 0.011649" pos="0.170562 0.021031 0.041246" type="box"/>
                <geom size="0.008 0.245507 0.041748" pos="-0.170562 0.021031 -0.078968" type="box"/>
                <geom size="0.008 0.245507 0.041748" pos="0.170562 0.021031 -0.078968" type="box"/>
                <geom size="0.198867 0.0095 0.131375" pos="0 -0.233977 0" type="box"/>
                <geom size="0.178822 0.008 0.084491" pos="0 0.260372 -0.037996" type="box"/>
                <geom size="0.178822 0.245507 0.008" pos="0 0.021031 -0.113735" type="box"/>
                <geom size="0.01 0.0065 0.0065" pos="-0.0760215 -0.250753 0.0854179" quat="0.707107 0 0 0.707107" type="box"/>
                <geom size="0.01 0.0065 0.0065" pos="0.0839785 -0.250753 0.0854179" quat="0.707107 0 0 0.707107" type="box"/>
                <geom size="0.0065 0.086516 0.0065" pos="0.00397854 -0.267252 0.0854179" quat="0.707107 0 0 0.707107" type="box"/>
            </body>
            <body name="cabinet6_drawer3" pos="0.327564 3.58453 0.297298" quat="0.707107 0 0 0.707107" gravcomp="0">
                <joint name="cabinet6_drawer3_joint" pos="0 0 0" axis="0 -1 0" type="slide" range="0 0.45"/>
                <geom size="0.008 0.245507 0.011638" pos="-0.170562 0.021031 -0.00926" type="box"/>
                <geom size="0.008 0.245507 0.011638" pos="0.170562 0.021031 -0.00926" type="box"/>
                <geom size="0.008 0.245507 0.041711" pos="-0.170562 0.021031 -0.129424" type="box"/>
                <geom size="0.008 0.245507 0.041711" pos="0.170562 0.021031 -0.129424" type="box"/>
                <geom size="0.198867 0.0095 0.197867" pos="0 -0.233977 0" type="box"/>
                <geom size="0.178822 0.008 0.084105" pos="0 0.260372 -0.088821" type="box"/>
                <geom size="0.178822 0.245507 0.008" pos="0 0.021031 -0.164582" type="box"/>
                <geom size="0.01 0.0065 0.0065" pos="-0.0759722 -0.251013 0.151166" quat="0.707107 0 0 0.707107" type="box"/>
                <geom size="0.01 0.0065 0.0065" pos="0.0840278 -0.251013 0.151166" quat="0.707107 0 0 0.707107" type="box"/>
                <geom size="0.0065 0.086516 0.0065" pos="0.00402777 -0.267511 0.151166" quat="0.707107 0 0 0.707107" type="box"/>
            </body>
            <body name="counter_sink_tap_switch" pos="2.75435 3.3144 1.01332" quat="0.707107 0 0 0.707107" gravcomp="0">
                <joint name="counter_sink_tap_temperature_joint" pos="0 0 0" axis="1 0 0" range="-1.5708 1.5708"/>
                <geom size="0.0005 0.0005 0.0005" type="box"/>
                <body name="counter_sink_tap" pos="0 0 0" gravcomp="0">
                    <joint name="counter_sink_switch_joint" pos="0 0 0" axis="0 -1 0" range="0 0.392699"/>
                    <geom size="0.022432 0.012197" pos="-0.007501 0 0" quat="0.707107 0 0.707107 0" type="cylinder"/>
                    <geom size="0.005 0.027997" pos="-0.012886 0 0.048989" type="cylinder"/>
                </body>
            </body>
            <body name="dishwasher_front" pos="2.34807 3.96324 0.169551" quat="0.707107 0 0 -0.707107" gravcomp="0">
                <joint name="dishwasher_front_joint" pos="0 0 0" axis="1 0 0" range="0 1.5708"/>
                <geom size="0.304987 0.009444 0.397179" pos="0 -0.04 0.329015" type="box"/>
                <geom size="0.287469 0.015 0.339603" pos="-0.01 -0.015728 0.334215" type="box"/>
                <geom size="0.01 0.0065 0.0065" pos="-0.0969432 -0.0588262 0.678848" quat="0.707107 0 0 0.707107" type="box"/>
                <geom size="0.01 0.0065 0.0065" pos="0.0630568 -0.0588262 0.678848" quat="0.707107 0 0 0.707107" type="box"/>
                <geom size="0.0065 0.086516 0.0065" pos="-0.0169432 -0.0753247 0.678848" quat="0.707107 0 0 0.707107" type="box"/>
            </body>
            <body name="dishwasher_tray1" pos="2.61821 3.97091 0.3894" quat="0.707107 0 0 -0.707107" gravcomp="0">
                <joint name="dishwasher_tray1_joint" pos="0 0 0" axis="0 -1 0" type="slide" range="0 0.5"/>
                <geom type="mesh" mesh="SM_Dishwasher_Tray_01"/>
            </body>
            <body name="dishwasher_tray2" pos="2.60161 3.97091 0.564592" quat="0.707107 0 0 -0.707107" gravcomp="0">
                <joint name="dishwasher_tray2_joint" pos="0 0 0" axis="0 -1 0" type="slide" range="0 0.3"/>
                <geom type="mesh" mesh="SM_Dishwasher_Tray_02"/>
            </body>
            <body name="dishwasher_tray3" pos="2.62207 3.97668 0.773578" quat="0.707107 0 0 -0.707107" gravcomp="0">
                <joint name="dishwasher_tray3_joint" pos="0 0 0" axis="0 -1 0" type="slide" range="0 0.3"/>
                <geom type="mesh" mesh="SM_Dishwasher_Tray_03"/>
            </body>
            <body name="sink_drawer1" pos="2.54181 3.37246 0.497681" quat="0.707107 0 0 -0.707107" gravcomp="0">
                <joint name="sink_drawer1_joint" pos="0 0 0" axis="0 -1 0" type="slide" range="0 0.45"/>
                <geom size="0.298258 0.009388 0.397013" pos="0 -0.233976 0" type="box"/>
                <geom size="0.269754 0.009017 0.084742" pos="0 0.259483 -0.288887" type="box"/>
                <geom size="0.0075 0.249028 0.042" pos="0.268047 0.025012 -0.08949" type="box"/>
                <geom size="0.0075 0.249028 0.042" pos="-0.268047 0.025012 -0.08949" type="box"/>
                <geom size="0.0075 0.249028 0.011648" pos="0.268047 0.025012 -0.208727" type="box"/>
                <geom size="0.0075 0.249028 0.011648" pos="-0.268047 0.025012 -0.208727" type="box"/>
                <geom size="0.0075 0.249028 0.043609" pos="0.268047 0.025012 -0.33085" type="box"/>
                <geom size="0.0075 0.249028 0.043609" pos="-0.268047 0.025012 -0.33085" type="box"/>
                <geom size="0.031012 0.249028 0.008" pos="0.246033 0.025012 -0.04" type="box"/>
                <geom size="0.031012 0.249028 0.008" pos="-0.246033 0.025012 -0.04" type="box"/>
                <geom size="0.277046 0.010504 0.008" pos="0 -0.213959 -0.04" type="box"/>
                <geom size="0.277046 0.058653 0.008" pos="0 0.21583 -0.04" type="box"/>
                <geom size="0.008426 0.074789 0.173305" pos="-0.00535 0.086505 -0.198155" type="box"/>
                <geom size="0.008426 0.074789 0.173305" pos="-0.211412 0.086505 -0.198155" type="box"/>
                <geom size="0.109826 0.008356 0.173305" pos="-0.109826 0.152938 -0.198155" type="box"/>
                <geom size="0.109826 0.008356 0.173305" pos="-0.109826 0.02 -0.198155" type="box"/>
                <geom size="0.109826 0.074789 0.00085" pos="-0.109826 0.086505 -0.372315" type="box"/>
                <geom size="0.008426 0.074789 0.173305" pos="0.00535 0.086505 -0.198155" type="box"/>
                <geom size="0.008426 0.074789 0.173305" pos="0.211412 0.086505 -0.198155" type="box"/>
                <geom size="0.109826 0.008426 0.173305" pos="0.109826 0.152938 -0.198155" type="box"/>
                <geom size="0.109826 0.008426 0.173305" pos="0.109826 0.02 -0.198155" type="box"/>
                <geom size="0.109826 0.074789 0.00085" pos="0.109826 0.086505 -0.372315" type="box"/>
                <geom size="0.008426 0.109729 0.173305" pos="-0.221355 -0.098209 -0.198155" type="box"/>
                <geom size="0.008426 0.109729 0.173305" pos="-0.088435 -0.098209 -0.198155" type="box"/>
                <geom size="0.074691 0.008426 0.173305" pos="-0.155 0.003041 -0.198155" type="box"/>
                <geom size="0.074691 0.008426 0.173305" pos="-0.155 -0.199821 -0.198155" type="box"/>
                <geom size="0.074691 0.109729 0.00085" pos="-0.155 -0.098209 -0.372315" type="box"/>
                <geom size="0.008426 0.109729 0.173305" pos="0.221355 -0.098209 -0.198155" type="box"/>
                <geom size="0.008426 0.109729 0.173305" pos="-0.071323 -0.098209 -0.198155" type="box"/>
                <geom size="0.154749 0.008426 0.173305" pos="0.075302 0.003041 -0.198155" type="box"/>
                <geom size="0.154749 0.008426 0.173305" pos="0.075302 -0.199821 -0.198155" type="box"/>
                <geom size="0.154749 0.109729 0.00085" pos="0.075302 -0.098209 -0.372315" type="box"/>
                <geom size="0.01 0.0065 0.0065" pos="-0.0766866 -0.252893 0.350717" quat="0.707107 0 0 0.707107" type="box"/>
                <geom size="0.01 0.0065 0.0065" pos="0.0833134 -0.252893 0.350717" quat="0.707107 0 0 0.707107" type="box"/>
                <geom size="0.0065 0.086516 0.0065" pos="0.00331339 -0.269392 0.350717" quat="0.707107 0 0 0.707107" type="box"/>
            </body>
            <body name="sink_drawer2" pos="2.51969 3.37374 0.658859" quat="0.707107 0 0 -0.707107" gravcomp="0">
                <joint name="sink_drawer2_joint" pos="0 0 0" axis="0 -1 0" type="slide" range="0 0.3"/>
                <geom size="0.008 0.188013 0.041105" pos="-0.270604 0.002535 -0.000733" type="box"/>
                <geom size="0.008 0.188013 0.041105" pos="0.270604 0.002535 -0.000733" type="box"/>
                <geom size="0.032497 0.0085 0.049661" pos="-0.248473 -0.191981 0.000834" type="box"/>
                <geom size="0.032497 0.0085 0.049661" pos="0.248473 -0.191981 0.000834" type="box"/>
                <geom size="0.216977 0.0085 0.049" pos="0 -0.191981 -0.0015" type="box"/>
                <geom size="0.278678 0.008 0.0415" pos="0 0.184382 -0.0024" type="box"/>
                <geom size="0.278678 0.188013 0.008" pos="0 0.002535 -0.036496" type="box"/>
            </body>
            <body name="cabinet9_drawer1" pos="2.54209 2.77093 0.826152" quat="0.707107 0 0 -0.707107" gravcomp="0">
                <joint name="cabinet9_drawer1_joint" pos="0 0 0" axis="0 -1 0" type="slide" range="0 0.45"/>
                <geom size="0.008 0.245507 0.042633" pos="-0.270267 0.021031 -0.01336" type="box"/>
                <geom size="0.008 0.245507 0.042633" pos="0.270267 0.021031 -0.01336" type="box"/>
                <geom size="0.298468 0.0095 0.064993" pos="0 -0.233977 0" type="box"/>
                <geom size="0.269804 0.008 0.042633" pos="0 0.260372 -0.01336" type="box"/>
                <geom size="0.269804 0.245507 0.0075" pos="0 0.021031 -0.047595" type="box"/>
                <geom size="0.01 0.0065 0.0065" pos="-0.0814236 -0.2537 0.0167695" quat="0.707107 0 0 0.707107" type="box"/>
                <geom size="0.01 0.0065 0.0065" pos="0.0785764 -0.2537 0.0167695" quat="0.707107 0 0 0.707107" type="box"/>
                <geom size="0.0065 0.086516 0.0065" pos="-0.00142363 -0.270199 0.0167695" quat="0.707107 0 0 0.707107" type="box"/>
            </body>
            <body name="cabinet9_drawer2" pos="2.54213 2.77204 0.629012" quat="0.707107 0 0 -0.707107" gravcomp="0">
                <joint name="cabinet9_drawer2_joint" pos="0 0 0" axis="0 -1 0" type="slide" range="0 0.45"/>
                <geom size="0.008 0.245507 0.011649" pos="-0.270267 0.021031 0.041246" type="box"/>
                <geom size="0.008 0.245507 0.011649" pos="0.270267 0.021031 0.041246" type="box"/>
                <geom size="0.008 0.245507 0.041748" pos="-0.270267 0.021031 -0.078968" type="box"/>
                <geom size="0.008 0.245507 0.041748" pos="0.270267 0.021031 -0.078968" type="box"/>
                <geom size="0.298468 0.0095 0.131375" pos="0 -0.233977 0" type="box"/>
                <geom size="0.269804 0.008 0.084491" pos="0 0.260372 -0.037996" type="box"/>
                <geom size="0.269804 0.245507 0.008" pos="0 0.021031 -0.113735" type="box"/>
                <geom size="0.01 0.0065 0.0065" pos="-0.0810641 -0.254602 0.0850084" quat="0.707107 0 0 0.707107" type="box"/>
                <geom size="0.01 0.0065 0.0065" pos="0.0789359 -0.254602 0.0850084" quat="0.707107 0 0 0.707107" type="box"/>
                <geom size="0.0065 0.086516 0.0065" pos="-0.00106413 -0.2711 0.0850084" quat="0.707107 0 0 0.707107" type="box"/>
            </body>
            <body name="cabinet9_drawer3" pos="2.54243 2.77102 0.297954" quat="0.707107 0 0 -0.707107" gravcomp="0">
                <joint name="cabinet9_drawer3_joint" pos="0 0 0" axis="0 -1 0" type="slide" range="0 0.45"/>
                <geom size="0.008 0.245507 0.011638" pos="-0.270267 0.021031 -0.00926" type="box"/>
                <geom size="0.008 0.245507 0.011638" pos="0.270267 0.021031 -0.00926" type="box"/>
                <geom size="0.008 0.245507 0.041711" pos="-0.270267 0.021031 -0.129424" type="box"/>
                <geom size="0.008 0.245507 0.041711" pos="0.270267 0.021031 -0.129424" type="box"/>
                <geom size="0.298468 0.0095 0.197867" pos="0 -0.233977 0" type="box"/>
                <geom size="0.269804 0.008 0.084105" pos="0 0.260372 -0.088821" type="box"/>
                <geom size="0.269804 0.245507 0.008" pos="0 0.021031 -0.164582" type="box"/>
                <geom size="0.01 0.0065 0.0065" pos="-0.0810287 -0.252773 0.15027" quat="0.707107 0 0 0.707107" type="box"/>
                <geom size="0.01 0.0065 0.0065" pos="0.0789713 -0.252773 0.15027" quat="0.707107 0 0 0.707107" type="box"/>
                <geom size="0.0065 0.086516 0.0065" pos="-0.00102875 -0.269271 0.15027" quat="0.707107 0 0 0.707107" type="box"/>
            </body>
            <body name="cabinet10_drawer1" pos="2.54203 2.27254 0.826772" quat="0.707107 0 0 -0.707107" gravcomp="0">
                <joint name="cabinet10_drawer1_joint" pos="0 0 0" axis="0 -1 0" type="slide" range="0 0.45"/>
                <geom size="0.008 0.245507 0.042633" pos="-0.170562 0.021031 -0.01336" type="box"/>
                <geom size="0.008 0.245507 0.042633" pos="0.170562 0.021031 -0.01336" type="box"/>
                <geom size="0.198867 0.0095 0.064993" pos="0 -0.233977 0" type="box"/>
                <geom size="0.178822 0.008 0.042633" pos="0 0.260372 -0.01336" type="box"/>
                <geom size="0.178822 0.245507 0.0075" pos="0 0.021031 -0.047595" type="box"/>
                <geom size="0.01 0.0065 0.0065" pos="-0.078754 -0.250514 0.0172039" quat="0.707107 0 0 0.707107" type="box"/>
                <geom size="0.01 0.0065 0.0065" pos="0.081246 -0.250514 0.0172039" quat="0.707107 0 0 0.707107" type="box"/>
                <geom size="0.0065 0.086516 0.0065" pos="0.00124599 -0.267013 0.0172039" quat="0.707107 0 0 0.707107" type="box"/>
            </body>
            <body name="cabinet10_drawer2" pos="2.54228 2.27185 0.629172" quat="0.707107 0 0 -0.707107" gravcomp="0">
                <joint name="cabinet10_drawer2_joint" pos="0 0 0" axis="0 -1 0" type="slide" range="0 0.45"/>
                <geom size="0.008 0.245507 0.011649" pos="-0.170562 0.021031 0.041246" type="box"/>
                <geom size="0.008 0.245507 0.011649" pos="0.170562 0.021031 0.041246" type="box"/>
                <geom size="0.008 0.245507 0.041748" pos="-0.170562 0.021031 -0.078968" type="box"/>
                <geom size="0.008 0.245507 0.041748" pos="0.170562 0.021031 -0.078968" type="box"/>
                <geom size="0.198867 0.0095 0.131375" pos="0 -0.233977 0" type="box"/>
                <geom size="0.178822 0.008 0.084491" pos="0 0.260372 -0.037996" type="box"/>
                <geom size="0.178822 0.245507 0.008" pos="0 0.021031 -0.113735" type="box"/>
                <geom size="0.01 0.0065 0.0065" pos="-0.0760215 -0.250753 0.0854179" quat="0.707107 0 0 0.707107" type="box"/>
                <geom size="0.01 0.0065 0.0065" pos="0.0839785 -0.250753 0.0854179" quat="0.707107 0 0 0.707107" type="box"/>
                <geom size="0.0065 0.086516 0.0065" pos="0.00397854 -0.267252 0.0854179" quat="0.707107 0 0 0.707107" type="box"/>
            </body>
            <body name="cabinet10_drawer3" pos="2.54259 2.27155 0.297152" quat="0.707107 0 0 -0.707107" gravcomp="0">
                <joint name="cabinet10_drawer3_joint" pos="0 0 0" axis="0 -1 0" type="slide" range="0 0.45"/>
                <geom size="0.008 0.245507 0.011638" pos="-0.170562 0.021031 -0.00926" type="box"/>
                <geom size="0.008 0.245507 0.011638" pos="0.170562 0.021031 -0.00926" type="box"/>
                <geom size="0.008 0.245507 0.041711" pos="-0.170562 0.021031 -0.129424" type="box"/>
                <geom size="0.008 0.245507 0.041711" pos="0.170562 0.021031 -0.129424" type="box"/>
                <geom size="0.198867 0.0095 0.197867" pos="0 -0.233977 0" type="box"/>
                <geom size="0.178822 0.008 0.084105" pos="0 0.260372 -0.088821" type="box"/>
                <geom size="0.178822 0.245507 0.008" pos="0 0.021031 -0.164582" type="box"/>
                <geom size="0.01 0.0065 0.0065" pos="-0.0759722 -0.251013 0.151166" quat="0.707107 0 0 0.707107" type="box"/>
                <geom size="0.01 0.0065 0.0065" pos="0.0840278 -0.251013 0.151166" quat="0.707107 0 0 0.707107" type="box"/>
                <geom size="0.0065 0.086516 0.0065" pos="0.00402777 -0.267511 0.151166" quat="0.707107 0 0 0.707107" type="box"/>
            </body>
            <body name="cabinet11_drawer1" pos="2.54211 1.6222 0.828013" quat="0.707107 0 0 -0.707107" gravcomp="0">
                <joint name="cabinet11_drawer1_joint" pos="0 0 0" axis="0 -1 0" type="slide" range="0 0.45"/>
                <geom size="0.008 0.245507 0.042633" pos="-0.418233 0.021031 -0.01336" type="box"/>
                <geom size="0.008 0.245507 0.042633" pos="0.418233 0.021031 -0.01336" type="box"/>
                <geom size="0.448341 0.0095 0.064993" pos="0 -0.233977 0" type="box"/>
                <geom size="0.419788 0.008 0.042633" pos="0 0.260372 -0.01336" type="box"/>
                <geom size="0.419788 0.245507 0.0075" pos="0 0.021031 -0.047595" type="box"/>
                <geom size="0.01 0.0065 0.0065" pos="-0.078754 -0.250514 0.0172039" quat="0.707107 0 0 0.707107" type="box"/>
                <geom size="0.01 0.0065 0.0065" pos="0.081246 -0.250514 0.0172039" quat="0.707107 0 0 0.707107" type="box"/>
                <geom size="0.0065 0.086516 0.0065" pos="0.00124599 -0.267013 0.0172039" quat="0.707107 0 0 0.707107" type="box"/>
            </body>
            <body name="cabinet11_drawer2" pos="2.54263 1.62202 0.629023" quat="0.707107 0 0 -0.707107" gravcomp="0">
                <joint name="cabinet11_drawer2_joint" pos="0 0 0" axis="0 -1 0" type="slide" range="0 0.45"/>
                <geom size="0.008 0.245507 0.011649" pos="-0.418233 0.021031 0.041246" type="box"/>
                <geom size="0.008 0.245507 0.011649" pos="0.418233 0.021031 0.041246" type="box"/>
                <geom size="0.008 0.245507 0.041748" pos="-0.418233 0.021031 -0.078968" type="box"/>
                <geom size="0.008 0.245507 0.041748" pos="0.418233 0.021031 -0.078968" type="box"/>
                <geom size="0.448341 0.0095 0.131375" pos="0 -0.233977 0" type="box"/>
                <geom size="0.419788 0.008 0.084491" pos="0 0.260372 -0.037996" type="box"/>
                <geom size="0.419788 0.245507 0.008" pos="0 0.021031 -0.113735" type="box"/>
                <geom size="0.01 0.0065 0.0065" pos="-0.0760215 -0.250753 0.0854179" quat="0.707107 0 0 0.707107" type="box"/>
                <geom size="0.01 0.0065 0.0065" pos="0.0839785 -0.250753 0.0854179" quat="0.707107 0 0 0.707107" type="box"/>
                <geom size="0.0065 0.086516 0.0065" pos="0.00397854 -0.267252 0.0854179" quat="0.707107 0 0 0.707107" type="box"/>
            </body>
            <body name="cabinet11_drawer3" pos="2.54216 1.62302 0.296537" quat="0.707107 0 0 -0.707107" gravcomp="0">
                <joint name="cabinet11_drawer3_joint" pos="0 0 0" axis="0 -1 0" type="slide" range="0 0.45"/>
                <geom size="0.008 0.245507 0.011638" pos="-0.418233 0.021031 -0.00926" type="box"/>
                <geom size="0.008 0.245507 0.011638" pos="0.418233 0.021031 -0.00926" type="box"/>
                <geom size="0.008 0.245507 0.041711" pos="-0.418233 0.021031 -0.129424" type="box"/>
                <geom size="0.008 0.245507 0.041711" pos="0.418233 0.021031 -0.129424" type="box"/>
                <geom size="0.448341 0.0095 0.197867" pos="0 -0.233977 0" type="box"/>
                <geom size="0.419788 0.008 0.084105" pos="0 0.260372 -0.088821" type="box"/>
                <geom size="0.419788 0.245507 0.008" pos="0 0.021031 -0.164582" type="box"/>
                <geom size="0.01 0.0065 0.0065" pos="-0.0759722 -0.251013 0.151166" quat="0.707107 0 0 0.707107" type="box"/>
                <geom size="0.01 0.0065 0.0065" pos="0.0840278 -0.251013 0.151166" quat="0.707107 0 0 0.707107" type="box"/>
                <geom size="0.0065 0.086516 0.0065" pos="0.00402777 -0.267511 0.151166" quat="0.707107 0 0 0.707107" type="box"/>
            </body>
        </body>
    </worldbody>
    <equality />

    <contact>
        <exclude body1="iai_apartment_with_window4" body2="wardrobe_door_left" />
        <exclude body1="iai_apartment_with_window4" body2="wardrobe_door_right" />
        <exclude body1="iai_apartment_with_window4" body2="coffee_table_drawer" />
        <exclude body1="iai_apartment_with_window4" body2="cabinet1_door" />
        <exclude body1="iai_apartment_with_window4" body2="cabinet1_drawer1" />
        <exclude body1="iai_apartment_with_window4" body2="cabinet1_drawer2" />
        <exclude body1="iai_apartment_with_window4" body2="oven_door" />
        <exclude body1="iai_apartment_with_window4" body2="cabinet2_door" />
        <exclude body1="iai_apartment_with_window4" body2="cabinet2_drawer1" />
        <exclude body1="iai_apartment_with_window4" body2="cabinet2_drawer2" />
        <exclude body1="iai_apartment_with_window4" body2="cabinet2_drawer3" />
        <exclude body1="iai_apartment_with_window4" body2="cabinet2_drawer4" />
        <exclude body1="iai_apartment_with_window4" body2="cabinet2_drawer5" />
        <exclude body1="iai_apartment_with_window4" body2="cabinet2_drawer6" />
        <exclude body1="iai_apartment_with_window4" body2="fridge_door1" />
        <exclude body1="iai_apartment_with_window4" body2="fridge_door2" />
        <exclude body1="iai_apartment_with_window4" body2="fridge_drawer1" />
        <exclude body1="iai_apartment_with_window4" body2="fridge_drawer2" />
        <exclude body1="iai_apartment_with_window4" body2="fridge_drawer3" />
        <exclude body1="iai_apartment_with_window4" body2="fridge_drawer4" />
        <exclude body1="iai_apartment_with_window4" body2="fridge_drawer5" />
        <exclude body1="iai_apartment_with_window4" body2="cabinet5_drawer1" />
        <exclude body1="iai_apartment_with_window4" body2="cabinet5_drawer2" />
        <exclude body1="iai_apartment_with_window4" body2="cabinet5_drawer3" />
        <exclude body1="iai_apartment_with_window4" body2="cabinet6_drawer1" />
        <exclude body1="iai_apartment_with_window4" body2="cabinet6_drawer2" />
        <exclude body1="iai_apartment_with_window4" body2="cabinet6_drawer3" />
        <exclude body1="iai_apartment_with_window4" body2="fridge_drawer4" />
        <exclude body1="iai_apartment_with_window4" body2="fridge_drawer5" />
        <exclude body1="iai_apartment_with_window4" body2="counter_sink_tap_switch" />
        <exclude body1="iai_apartment_with_window4" body2="counter_sink_tap" />
        <exclude body1="counter_sink_tap_switch" body2="counter_sink_tap" />
        <exclude body1="iai_apartment_with_window4" body2="dishwasher_front" />
        <exclude body1="iai_apartment_with_window4" body2="dishwasher_tray1" />
        <exclude body1="iai_apartment_with_window4" body2="dishwasher_tray2" />
        <exclude body1="iai_apartment_with_window4" body2="dishwasher_tray3" />
        <exclude body1="iai_apartment_with_window4" body2="sink_drawer1" />
        <exclude body1="iai_apartment_with_window4" body2="sink_drawer2" />
        <exclude body1="iai_apartment_with_window4" body2="cabinet9_drawer1" />
        <exclude body1="iai_apartment_with_window4" body2="cabinet9_drawer2" />
        <exclude body1="iai_apartment_with_window4" body2="cabinet9_drawer3" />
        <exclude body1="iai_apartment_with_window4" body2="cabinet10_drawer1" />
        <exclude body1="iai_apartment_with_window4" body2="cabinet10_drawer2" />
        <exclude body1="iai_apartment_with_window4" body2="cabinet10_drawer3" />
        <exclude body1="iai_apartment_with_window4" body2="cabinet11_drawer1" />
        <exclude body1="iai_apartment_with_window4" body2="cabinet11_drawer2" />
        <exclude body1="iai_apartment_with_window4" body2="cabinet11_drawer3" />
        <exclude body1="iai_apartment_with_window4" body2="window4_left" />
        <exclude body1="iai_apartment_with_window4" body2="window4_right" />
    </contact>
</mujoco>